Workbook

Sheet DASHBOARD
A1: DASHBOARD DE PRODUTIVIDADE
A3: Indicador | B3: Resultado | D3: Equipe | E3: Atividades atrasadas | F3: Concluídas avaliáveis | G3: Taxa de atraso
A4: Total de atividades | B4: =COUNTA('DADOS TRATADOS'!A2:A1000) -> 40 | D4: Equipe Norte | E4: =COUNTIFS('DADOS TRATADOS'!C:C,D4,'DADOS TRATADOS'!I:I,"Atrasada") -> 10 | F4: =COUNTIFS('DADOS TRATADOS'!C:C,D4,'DADOS TRATADOS'!I:I,"Atrasada")+COUNTIFS('DADOS TRATADOS'!C:C,D4,'DADOS TRATADOS'!I:I,"No prazo") -> 13 | G4: =IFERROR(E4/F4,0) -> 0.76923077
A5: Atividades concluídas | B5: =COUNTIF('DADOS TRATADOS'!E2:E1000,"Concluída") -> 34 | D5: Equipe Sul | E5: =COUNTIFS('DADOS TRATADOS'!C:C,D5,'DADOS TRATADOS'!I:I,"Atrasada") -> 4 | F5: =COUNTIFS('DADOS TRATADOS'!C:C,D5,'DADOS TRATADOS'!I:I,"Atrasada")+COUNTIFS('DADOS TRATADOS'!C:C,D5,'DADOS TRATADOS'!I:I,"No prazo") -> 10 | G5: =IFERROR(E5/F5,0) -> 0.4
A6: Atividades pendentes | B6: =COUNTIF('DADOS TRATADOS'!E2:E1000,"Pendente") -> 6 | D6: Equipe Centro | E6: =COUNTIFS('DADOS TRATADOS'!C:C,D6,'DADOS TRATADOS'!I:I,"Atrasada") -> 2 | F6: =COUNTIFS('DADOS TRATADOS'!C:C,D6,'DADOS TRATADOS'!I:I,"Atrasada")+COUNTIFS('DADOS TRATADOS'!C:C,D6,'DADOS TRATADOS'!I:I,"No prazo") -> 9 | G6: =IFERROR(E6/F6,0) -> 0.22222222
A7: Atividades atrasadas | B7: =COUNTIF('DADOS TRATADOS'!I2:I1000,"Atrasada") -> 16 | D7: Não informada | E7: =COUNTIFS('DADOS TRATADOS'!C:C,D7,'DADOS TRATADOS'!I:I,"Atrasada") -> 0 | F7: =COUNTIFS('DADOS TRATADOS'!C:C,D7,'DADOS TRATADOS'!I:I,"Atrasada")+COUNTIFS('DADOS TRATADOS'!C:C,D7,'DADOS TRATADOS'!I:I,"No prazo") -> 1 | G7: =IFERROR(E7/F7,0) -> 0
A8: Concluídas no prazo | B8: =COUNTIF('DADOS TRATADOS'!I2:I1000,"No prazo") -> 17
A9: Sem dados de prazo | B9: =COUNTIF('DADOS TRATADOS'!I2:I1000,"Sem dados") -> 1
A11: Taxa de cuprimento do prazo | B11: =IFERROR(B8/(B7+B8),0) -> 0.51515152
A14: Tipo de serviço | B14: Atividades atrasadas | C14: Concluídas avaliáveis | D14: Taxa de atraso
A15: Instalação | B15: =COUNTIFS('DADOS TRATADOS'!D:D,A15,'DADOS TRATADOS'!I:I,"Atrasada") -> 4 | C15: =COUNTIFS('DADOS TRATADOS'!D:D,A15,'DADOS TRATADOS'!I:I,"Atrasada")+COUNTIFS('DADOS TRATADOS'!D:D,A15,'DADOS TRATADOS'!I:I,"No prazo") -> 8 | D15: =IFERROR(B15/C15,0) -> 0.5
A16: Manutenção | B16: =COUNTIFS('DADOS TRATADOS'!D:D,A16,'DADOS TRATADOS'!I:I,"Atrasada") -> 6 | C16: =COUNTIFS('DADOS TRATADOS'!D:D,A16,'DADOS TRATADOS'!I:I,"Atrasada")+COUNTIFS('DADOS TRATADOS'!D:D,A16,'DADOS TRATADOS'!I:I,"No prazo") -> 10 | D16: =IFERROR(B16/C16,0) -> 0.6
A17: Vistoria | B17: =COUNTIFS('DADOS TRATADOS'!D:D,A17,'DADOS TRATADOS'!I:I,"Atrasada") -> 2 | C17: =COUNTIFS('DADOS TRATADOS'!D:D,A17,'DADOS TRATADOS'!I:I,"Atrasada")+COUNTIFS('DADOS TRATADOS'!D:D,A17,'DADOS TRATADOS'!I:I,"No prazo") -> 8 | D17: =IFERROR(B17/C17,0) -> 0.25
A18: Reparo de fibra | B18: =COUNTIFS('DADOS TRATADOS'!D:D,A18,'DADOS TRATADOS'!I:I,"Atrasada") -> 4 | C18: =COUNTIFS('DADOS TRATADOS'!D:D,A18,'DADOS TRATADOS'!I:I,"Atrasada")+COUNTIFS('DADOS TRATADOS'!D:D,A18,'DADOS TRATADOS'!I:I,"No prazo") -> 7 | D18: =IFERROR(B18/C18,0) -> 0.57142857
A19: TOTAL | B19: =SUM(B15:B18) -> 16

Sheet DADOS TRATADOS
A1: ID Atividade | B1: Data de abertura | C1: Equipe | D1: Tipo de serviço | E1: Status | F1: Tempo (dias) | G1: Prazo (dias) | H1: Qualidade dos dados | I1: Situação do prazo
A2: AT-1001 | B2: 46266 | C2: Equipe Norte | D2: Instalação | E2: Pendente | G2: 5 | H2: =IF(E2="","Verificar status",IF(E2="Concluída",IF(F2="","Dado ausente","Completo"),"Não aplicável")) -> Não aplicável | I2: =IF(E2<>"Concluída","Em aberto",IF(OR(F2="",G2=""),"Sem dados",IF(F2>G2,"Atrasada","No prazo"))) -> Em aberto
A3: AT-1002 | B3: 46267 | C3: Equipe Sul | D3: Vistoria | E3: Concluída | F3: 2 | G3: 5 | H3: =IF(E3="","Verificar status",IF(E3="Concluída",IF(F3="","Dado ausente","Completo"),"Não aplicável")) -> Completo | I3: =IF(E3<>"Concluída","Em aberto",IF(OR(F3="",G3=""),"Sem dados",IF(F3>G3,"Atrasada","No prazo"))) -> No prazo
A4: AT-1003 | B4: 46268 | C4: Equipe Centro | D4: Reparo de fibra | E4: Concluída | F4: 3 | G4: 5 | H4: =IF(E4="","Verificar status",IF(E4="Concluída",IF(F4="","Dado ausente","Completo"),"Não aplicável")) -> Completo | I4: =IF(E4<>"Concluída","Em aberto",IF(OR(F4="",G4=""),"Sem dados",IF(F4>G4,"Atrasada","No prazo"))) -> No prazo
A5: AT-1004 | B5: 46269 | C5: Equipe Norte | D5: Manutenção | E5: Concluída | F5: 6 | G5: 5 | H5: =IF(E5="","Verificar status",IF(E5="Concluída",IF(F5="","Dado ausente","Completo"),"Não aplicável")) -> Completo | I5: =IF(E5<>"Concluída","Em aberto",IF(OR(F5="",G5=""),"Sem dados",IF(F5>G5,"Atrasada","No prazo"))) -> Atrasada
A6: AT-1005 | B6: 46270 | C6: Equipe Sul | D6: Manutenção | E6: Concluída | F6: 6 | G6: 5 | H6: =IF(E6="","Verificar status",IF(E6="Concluída",IF(F6="","Dado ausente","Completo"),"Não aplicável")) -> Completo | I6: =IF(E6<>"Concluída","Em aberto",IF(OR(F6="",G6=""),"Sem dados",IF(F6>G6,"Atrasada","No prazo"))) -> Atrasada
A7: AT-1006 | B7: 46271 | C7: Equipe Norte | D7: Instalação | E7: Concluída | F7: 8 | G7: 5 | H7: =IF(E7="","Verificar status",IF(E7="Concluída",IF(F7="","Dado ausente","Completo"),"Não aplicável")) -> Completo | I7: =IF(E7<>"Concluída","Em aberto",IF(OR(F7="",G7=""),"Sem dados",IF(F7>G7,"Atrasada","No prazo"))) -> Atrasada
A8: AT-1007 | B8: 46272 | C8: Equipe Norte | D8: Vistoria | E8: Concluída | F8: 12 | G8: 5 | H8: =IF(E8="","Verificar status",IF(E8="Concluída",IF(F8="","Dado ausente","Completo"),"Não aplicável")) -> Completo | I8: =IF(E8<>"Concluída","Em aberto",IF(OR(F8="",G8=""),"Sem dados",IF(F8>G8,"Atrasada","No prazo"))) -> Atrasada
A9: AT-1008 | B9: 46273 | C9: Equipe Sul | D9: Reparo de fibra | E9: Pendente | G9: 5 | H9: =IF(E9="","Verificar status",IF(E9="Concluída",IF(F9="","Dado ausente","Completo"),"Não aplicável")) -> Não aplicável | I9: =IF(E9<>"Concluída","Em aberto",IF(OR(F9="",G9=""),"Sem dados",IF(F9>G9,"Atrasada","No prazo"))) -> Em aberto
A10: AT-1009 | B10: 46274 | C10: Equipe Centro | D10: Manutenção | E10: Concluída | F10: 5 | G10: 5 | H10: =IF(E10="","Verificar status",IF(E10="Concluída",IF(F10="","Dado ausente","Completo"),"Não aplicável")) -> Completo | I10: =IF(E10<>"Concluída","Em aberto",IF(OR(F10="",G10=""),"Sem dados",IF(F10>G10,"Atrasada","No prazo"))) -> No prazo
A11: AT-1010 | B11: 46275 | C11: Equipe Norte | D11: Manutenção | E11: Concluída | F11: 9 | G11: 5 | H11: =IF(E11="","Verificar status",IF(E11="Concluída",IF(F11="","Dado ausente","Completo"),"Não aplicável")) -> Completo | I11: =IF(E11<>"Concluída","Em aberto",IF(OR(F11="",G11=""),"Sem dados",IF(F11>G11,"Atrasada","No prazo"))) -> Atrasada
A12: AT-1011 | B12: 46276 | C12: Equipe Sul | D12: Instalação | E12: Concluída | F12: 1 | G12: 5 | H12: =IF(E12="","Verificar status",IF(E12="Concluída",IF(F12="","Dado ausente","Completo"),"Não aplicável")) -> Completo | I12: =IF(E12<>"Concluída","Em aberto",IF(OR(F12="",G12=""),"Sem dados",IF(F12>G12,"Atrasada","No prazo"))) -> No prazo
A13: AT-1012 | B13: 46277 | C13: Não informada | D13: Vistoria | E13: Concluída | F13: 2 | G13: 5 | H13: =IF(E13="","Verificar status",IF(E13="Concluída",IF(F13="","Dado ausente","Completo"),"Não aplicável")) -> Completo | I13: =IF(E13<>"Concluída","Em aberto",IF(OR(F13="",G13=""),"Sem dados",IF(F13>G13,"Atrasada","No prazo"))) -> No prazo
A14: AT-1013 | B14: 46278 | C14: Equipe Norte | D14: Vistoria | E14: Concluída | F14: 5 | G14: 5 | H14: =IF(E14="","Verificar status",IF(E14="Concluída",IF(F14="","Dado ausente","Completo"),"Não aplicável")) -> Completo | I14: =IF(E14<>"Concluída","Em aberto",IF(OR(F14="",G14=""),"Sem dados",IF(F14>G14,"Atrasada","No prazo"))) -> No prazo
A15: AT-1014 | B15: 46279 | C15: Equipe Sul | D15: Reparo de fibra | E15: Concluída | F15: 4 | G15: 5 | H15: =IF(E15="","Verificar status",IF(E15="Concluída",IF(F15="","Dado ausente","Completo"),"Não aplicável")) -> Completo | I15: =IF(E15<>"Concluída","Em aberto",IF(OR(F15="",G15=""),"Sem dados",IF(F15>G15,"Atrasada","No prazo"))) -> No prazo
A16: AT-1015 | B16: 46280 | C16: Equipe Centro | D16: Manutenção | E16: Pendente | G16: 5 | H16: =IF(E16="","Verificar status",IF(E16="Concluída",IF(F16="","Dado ausente","Completo"),"Não aplicável")) -> Não aplicável | I16: =IF(E16<>"Concluída","Em aberto",IF(OR(F16="",G16=""),"Sem dados",IF(F16>G16,"Atrasada","No prazo"))) -> Em aberto
A17: AT-1016 | B17: 46281 | C17: Equipe Norte | D17: Instalação | E17: Concluída | F17: 10 | G17: 5 | H17: =IF(E17="","Verificar status",IF(E17="Concluída",IF(F17="","Dado ausente","Completo"),"Não aplicável")) -> Completo | I17: =IF(E17<>"Concluída","Em aberto",IF(OR(F17="",G17=""),"Sem dados",IF(F17>G17,"Atrasada","No prazo"))) -> Atrasada
A18: AT-1017 | B18: 46282 | C18: Equipe Sul | D18: Instalação | E18: Concluída | F18: 10 | G18: 5 | H18: =IF(E18="","Verificar status",IF(E18="Concluída",IF(F18="","Dado ausente","Completo"),"Não aplicável")) -> Completo | I18: =IF(E18<>"Concluída","Em aberto",IF(OR(F18="",G18=""),"Sem dados",IF(F18>G18,"Atrasada","No prazo"))) -> Atrasada
A19: AT-1018 | B19: 46283 | C19: Equipe Centro | D19: Vistoria | E19: Concluída | F19: 2 | G19: 5 | H19: =IF(E19="","Verificar status",IF(E19="Concluída",IF(F19="","Dado ausente","Completo"),"Não aplicável")) -> Completo | I19: =IF(E19<>"Concluída","Em aberto",IF(OR(F19="",G19=""),"Sem dados",IF(F19>G19,"Atrasada","No prazo"))) -> No prazo
A20: AT-1019 | B20: 46284 | C20: Equipe Norte | D20: Reparo de fibra | E20: Concluída | G20: 5 | H20: =IF(E20="","Verificar status",IF(E20="Concluída",IF(F20="","Dado ausente","Completo"),"Não aplicável")) -> Dado ausente | I20: =IF(E20<>"Concluída","Em aberto",IF(OR(F20="",G20=""),"Sem dados",IF(F20>G20,"Atrasada","No prazo"))) -> Sem dados
A21: AT-1020 | B21: 46285 | C21: Equipe Norte | D21: Manutenção | E21: Concluída | F21: 7 | G21: 5 | H21: =IF(E21="","Verificar status",IF(E21="Concluída",IF(F21="","Dado ausente","Completo"),"Não aplicável")) -> Completo | I21: =IF(E21<>"Concluída","Em aberto",IF(OR(F21="",G21=""),"Sem dados",IF(F21>G21,"Atrasada","No prazo"))) -> Atrasada
A22: AT-1021 | B22: 46286 | C22: Equipe Centro | D22: Manutenção | E22: Concluída | F22: 1 | G22: 5 | H22: =IF(E22="","Verificar status",IF(E22="Concluída",IF(F22="","Dado ausente","Completo"),"Não aplicável")) -> Completo | I22: =IF(E22<>"Concluída","Em aberto",IF(OR(F22="",G22=""),"Sem dados",IF(F22>G22,"Atrasada","No prazo"))) -> No prazo
A23: AT-1022 | B23: 46287 | C23: Equipe Norte | D23: Instalação | E23: Pendente | G23: 5 | H23: =IF(E23="","Verificar status",IF(E23="Concluída",IF(F23="","Dado ausente","Completo"),"Não aplicável")) -> Não aplicável | I23: =IF(E23<>"Concluída","Em aberto",IF(OR(F23="",G23=""),"Sem dados",IF(F23>G23,"Atrasada","No prazo"))) -> Em aberto
A24: AT-1023 | B24: 46288 | C24: Equipe Sul | D24: Manutenção | E24: Concluída | F24: 3 | G24: 5 | H24: =IF(E24="","Verificar status",IF(E24="Concluída",IF(F24="","Dado ausente","Completo"),"Não aplicável")) -> Completo | I24: =IF(E24<>"Concluída","Em aberto",IF(OR(F24="",G24=""),"Sem dados",IF(F24>G24,"Atrasada","No prazo"))) -> No prazo
A25: AT-1024 | B25: 46289 | C25: Equipe Centro | D25: Reparo de fibra | E25: Concluída | F25: 4 | G25: 5 | H25: =IF(E25="","Verificar status",IF(E25="Concluída",IF(F25="","Dado ausente","Completo"),"Não aplicável")) -> Completo | I25: =IF(E25<>"Concluída","Em aberto",IF(OR(F25="",G25=""),"Sem dados",IF(F25>G25,"Atrasada","No prazo"))) -> No prazo
A26: AT-1025 | B26: 46290 | C26: Equipe Norte | D26: Reparo de fibra | E26: Concluída | F26: 8 | G26: 5 | H26: =IF(E26="","Verificar status",IF(E26="Concluída",IF(F26="","Dado ausente","Completo"),"Não aplicável")) -> Completo | I26: =IF(E26<>"Concluída","Em aberto",IF(OR(F26="",G26=""),"Sem dados",IF(F26>G26,"Atrasada","No prazo"))) -> Atrasada
A27: AT-1026 | B27: 46266 | C27: Equipe Sul | D27: Manutenção | E27: Concluída | F27: 8 | G27: 5 | H27: =IF(E27="","Verificar status",IF(E27="Concluída",IF(F27="","Dado ausente","Completo"),"Não aplicável")) -> Completo | I27: =IF(E27<>"Concluída","Em aberto",IF(OR(F27="",G27=""),"Sem dados",IF(F27>G27,"Atrasada","No prazo"))) -> Atrasada
A28: AT-1027 | B28: 46267 | C28: Equipe Centro | D28: Instalação | E28: Concluída | F28: 10 | G28: 5 | H28: =IF(E28="","Verificar status",IF(E28="Concluída",IF(F28="","Dado ausente","Completo"),"Não aplicável")) -> Completo | I28: =IF(E28<>"Concluída","Em aberto",IF(OR(F28="",G28=""),"Sem dados",IF(F28>G28,"Atrasada","No prazo"))) -> Atrasada
A29: AT-1028 | B29: 46268 | C29: Equipe Norte | D29: Vistoria | E29: Concluída | F29: 4 | G29: 5 | H29: =IF(E29="","Verificar status",IF(E29="Concluída",IF(F29="","Dado ausente","Completo"),"Não aplicável")) -> Completo | I29: =IF(E29<>"Concluída","Em aberto",IF(OR(F29="",G29=""),"Sem dados",IF(F29>G29,"Atrasada","No prazo"))) -> No prazo
A30: AT-1029 | B30: 46269 | C30: Equipe Sul | D30: Vistoria | E30: Pendente | G30: 5 | H30: =IF(E30="","Verificar status",IF(E30="Concluída",IF(F30="","Dado ausente","Completo"),"Não aplicável")) -> Não aplicável | I30: =IF(E30<>"Concluída","Em aberto",IF(OR(F30="",G30=""),"Sem dados",IF(F30>G30,"Atrasada","No prazo"))) -> Em aberto
A31: AT-1030 | B31: 46270 | C31: Equipe Centro | D31: Reparo de fibra | E31: Concluída | F31: 7 | G31: 5 | H31: =IF(E31="","Verificar status",IF(E31="Concluída",IF(F31="","Dado ausente","Completo"),"Não aplicável")) -> Completo | I31: =IF(E31<>"Concluída","Em aberto",IF(OR(F31="",G31=""),"Sem dados",IF(F31>G31,"Atrasada","No prazo"))) -> Atrasada
A32: AT-1031 | B32: 46271 | C32: Equipe Norte | D32: Manutenção | E32: Concluída | F32: 3 | G32: 5 | H32: =IF(E32="","Verificar status",IF(E32="Concluída",IF(F32="","Dado ausente","Completo"),"Não aplicável")) -> Completo | I32: =IF(E32<>"Concluída","Em aberto",IF(OR(F32="",G32=""),"Sem dados",IF(F32>G32,"Atrasada","No prazo"))) -> No prazo
A33: AT-1032 | B33: 46272 | C33: Equipe Sul | D33: Instalação | E33: Concluída | F33: 2 | G33: 5 | H33: =IF(E33="","Verificar status",IF(E33="Concluída",IF(F33="","Dado ausente","Completo"),"Não aplicável")) -> Completo | I33: =IF(E33<>"Concluída","Em aberto",IF(OR(F33="",G33=""),"Sem dados",IF(F33>G33,"Atrasada","No prazo"))) -> No prazo
A34: AT-1033 | B34: 46273 | C34: Equipe Centro | D34: Instalação | E34: Concluída | F34: 3 | G34: 5 | H34: =IF(E34="","Verificar status",IF(E34="Concluída",IF(F34="","Dado ausente","Completo"),"Não aplicável")) -> Completo | I34: =IF(E34<>"Concluída","Em aberto",IF(OR(F34="",G34=""),"Sem dados",IF(F34>G34,"Atrasada","No prazo"))) -> No prazo
A35: AT-1034 | B35: 46274 | C35: Equipe Norte | D35: Vistoria | E35: Concluída | F35: 6 | G35: 5 | H35: =IF(E35="","Verificar status",IF(E35="Concluída",IF(F35="","Dado ausente","Completo"),"Não aplicável")) -> Completo | I35: =IF(E35<>"Concluída","Em aberto",IF(OR(F35="",G35=""),"Sem dados",IF(F35>G35,"Atrasada","No prazo"))) -> Atrasada
A36: AT-1035 | B36: 46275 | C36: Equipe Sul | D36: Reparo de fibra | E36: Concluída | F36: 6 | G36: 5 | H36: =IF(E36="","Verificar status",IF(E36="Concluída",IF(F36="","Dado ausente","Completo"),"Não aplicável")) -> Completo | I36: =IF(E36<>"Concluída","Em aberto",IF(OR(F36="",G36=""),"Sem dados",IF(F36>G36,"Atrasada","No prazo"))) -> Atrasada
A37: AT-1036 | B37: 46276 | C37: Equipe Centro | D37: Manutenção | E37: Pendente | G37: 5 | H37: =IF(E37="","Verificar status",IF(E37="Concluída",IF(F37="","Dado ausente","Completo"),"Não aplicável")) -> Não aplicável | I37: =IF(E37<>"Concluída","Em aberto",IF(OR(F37="",G37=""),"Sem dados",IF(F37>G37,"Atrasada","No prazo"))) -> Em aberto
A38: AT-1037 | B38: 46277 | C38: Equipe Norte | D38: Manutenção | E38: Concluída | F38: 12 | G38: 5 | H38: =IF(E38="","Verificar status",IF(E38="Concluída",IF(F38="","Dado ausente","Completo"),"Não aplicável")) -> Completo | I38: =IF(E38<>"Concluída","Em aberto",IF(OR(F38="",G38=""),"Sem dados",IF(F38>G38,"Atrasada","No prazo"))) -> Atrasada
A39: AT-1038 | B39: 46278 | C39: Equipe Sul | D39: Instalação | E39: Concluída | F39: 2 | G39: 5 | H39: =IF(E39="","Verificar status",IF(E39="Concluída",IF(F39="","Dado ausente","Completo"),"Não aplicável")) -> Completo | I39: =IF(E39<>"Concluída","Em aberto",IF(OR(F39="",G39=""),"Sem dados",IF(F39>G39,"Atrasada","No prazo"))) -> No prazo
A40: AT-1039 | B40: 46279 | C40: Equipe Centro | D40: Vistoria | E40: Concluída | F40: 5 | G40: 5 | H40: =IF(E40="","Verificar status",IF(E40="Concluída",IF(F40="","Dado ausente","Completo"),"Não aplicável")) -> Completo | I40: =IF(E40<>"Concluída","Em aberto",IF(OR(F40="",G40=""),"Sem dados",IF(F40>G40,"Atrasada","No prazo"))) -> No prazo
...

Sheet BASE CRUA
A1: ID Atividade | B1: Data de abertura | C1: Equipe | D1: Tipo de serviço | E1: Status | F1: Tempo (dias) | G1: Prazo (dias)
A2: AT-1001 | B2: 46266 | C2: Equipe Norte | D2: Instalação | E2: Pendente | G2: 5
A3: AT-1002 | B3: 46267 | C3: Equipe Sul | D3: Vistoria | E3: Concluída | F3: 2 | G3: 5
A4: AT-1003 | B4: 46268 | C4: Equipe Centro | D4: Reparo de fibra | E4: Concluída | F4: 3 | G4: 5
A5: AT-1004 | B5: 46269 | C5: Equipe Norte | D5: Manutenção | E5: Concluída | F5: 6 | G5: 5
A6: AT-1005 | B6: 46270 | C6: Equipe Sul | D6: Manutenção | E6: Concluída | F6: 6 | G6: 5
A7: AT-1006 | B7: 46271 | C7: equipe norte | D7: Instalação | E7: Concluída | F7: 8 | G7: 5
A8: AT-1007 | B8: 46272 | C8: Equipe Norte | D8: Vistoria | E8: Concluída | F8: 12 | G8: 5
A9: AT-1008 | B9: 46273 | C9: Equipe Sul | D9: Reparo de fibra | E9: Pendente | G9: 5
A10: AT-1009 | B10: 46274 | C10: Equipe Centro | D10: manutencao | E10: Concluída | F10: 5 | G10: 5
A11: AT-1010 | B11: 46275 | C11: Equipe Norte | D11: Manutenção | E11: Concluída | F11: 9 | G11: 5
A12: AT-1011 | B12: 46276 | C12: Equipe Sul | D12: Instalação | E12: Concluída | F12: 1 | G12: 5
A13: AT-1012 | B13: 46277 | D13: Vistoria | E13: Concluída | F13: 2 | G13: 5
A15: AT-1013 | B15: 46278 | C15: Equipe Norte | D15: Vistoria | E15: Concluída | F15: 5 | G15: 5
A16: AT-1014 | B16: 46279 | C16: Equipe Sul | D16: Reparo de fibra | E16: Concluída | F16: 4 | G16: 5
A17: AT-1015 | B17: 46280 | C17: Equipe Centro | D17: Manutenção | E17: Pendente | G17: 5
A18: AT-1016 | B18: 46281 | C18: Equipe Norte | D18: Instalação | E18: concluida | F18: 10 | G18: 5
A19: AT-1017 | B19: 46282 | C19: Equipe Sul | D19: Instalação | E19: Concluída | F19: 10 | G19: 5
A20: AT-1018 | B20: 46283 | C20: Equipe Centro | D20: Vistoria | E20: Concluída | F20: 2 | G20: 5
A21: AT-1019 | B21: 46284 | C21: Equipe Norte | D21: Reparo de fibra | E21: Concluída | G21: 5
A22: AT-1020 | B22: 46285 | C22: equipe norte | D22: Manutenção | E22: Concluída | F22: 7 | G22: 5
A23: AT-1021 | B23: 46286 | C23: Equipe Centro | D23: Manutenção | E23: Concluída | F23: 1 | G23: 5
A24: AT-1022 | B24: 46287 | C24: Equipe Norte | D24: Instalação | E24: Pendente | G24: 5
A25: AT-1023 | B25: 46288 | C25: Equipe Sul | D25: manutencao | E25: Concluída | F25: 3 | G25: 5
A26: AT-1010 | B26: 46275 | C26: Equipe Norte | D26: Manutenção | E26: Concluída | F26: 9 | G26: 5
A27: AT-1024 | B27: 46289 | C27: Equipe Centro | D27: Reparo de fibra | E27: Concluída | F27: 4 | G27: 5
A28: AT-1025 | B28: 46290 | C28: Equipe Norte | D28: Reparo de fibra | E28: Concluída | F28: 8 | G28: 5
A29: AT-1026 | B29: 46266 | C29: Equipe Sul | D29: Manutenção | E29: Concluída | F29: 8 | G29: 5
A30: AT-1027 | B30: 46267 | C30: Equipe Centro | D30: Instalação | E30: Concluída | F30: 10 | G30: 5
A31: AT-1028 | B31: 46268 | C31: Equipe Norte | D31: Vistoria | E31: Concluída | F31: 4 | G31: 5
A32: AT-1029 | B32: 46269 | C32: Equipe Sul | D32: Vistoria | E32: Pendente | G32: 5
A33: AT-1030 | B33: 46270 | C33: Equipe Centro | D33: Reparo de fibra | E33: Concluída | F33: 7 | G33: 5
A34: AT-1031 | B34: 46271 | C34: Equipe Norte | D34: Manutenção | E34: Concluída | F34: 3 | G34: 5
A35: AT-1032 | B35: 46272 | C35: Equipe Sul | D35: Instalação | E35: Concluída | F35: 2 | G35: 5
A36: AT-1033 | B36: 46273 | C36: Equipe Centro | D36: Instalação | E36: Concluída | F36: 3 | G36: 5
A37: AT-1034 | B37: 46274 | C37: Equipe Norte | D37: Vistoria | E37: Concluída | F37: 6 | G37: 5
A38: AT-1035 | B38: 46275 | C38: Equipe Sul | D38: Reparo de fibra | E38: Concluída | F38: 6 | G38: 5
A39: AT-1036 | B39: 46276 | C39: Equipe Centro | D39: Manutenção | E39: Pendente | G39: 5
A40: AT-1037 | B40: 46277 | C40: Equipe Norte | D40: Manutenção | E40: Concluída | F40: 12 | G40: 5
A41: AT-1038 | B41: 46278 | C41: Equipe Sul | D41: Instalação | E41: Concluída | F41: 2 | G41: 5
...
